<?xml version='1.0' encoding='utf-8'?>
<robot xmlns:xacro="http://www.ros.org/wiki/xacro" name="panda">
  <xacro:include filename="panda_arm.urdf" />

  <joint name="panda_hand_joint" type="fixed">
    <parent link="panda_link7"/>
    <child link="panda_hand"/>
    <origin rpy="0 0 -0.785398163397" xyz="0 0 0.107"/>
  </joint>
  
  <link name="panda_hand">
    <visual>
      <geometry>
        <mesh filename="package://meshes/visual/hand.obj"/>
      </geometry>
      <material name="panda_gray"/>
    </visual>
    <collision>
      <geometry>
        <mesh filename="package://meshes/collision/hand.obj"/>
      </geometry>
      <material name="panda_gray"/>
    </collision>
    <inertial>
      <origin xyz="0 0 0" rpy="0 0 0"/>
      <mass value="0.68"/>
      <inertia ixx="0.1" ixy="0.0" ixz="0.0" iyy="0.1" iyz="0.0" izz="0.1"/>
    </inertial>
  </link>
  
  <link name="panda_finger_link1">
    <visual>
      <geometry>
        <mesh filename="package://meshes/visual/finger.obj"/>
      </geometry>
      <material name="panda_gray"/>
    </visual>
    <collision>
      <geometry>
        <mesh filename="package://meshes/collision/finger.obj"/>
      </geometry>
      <material name="panda_gray"/>
    </collision>
    <inertial>
      <origin xyz="0 0 0" rpy="0 0 0"/>
      <mass value="0.01"/>
      <inertia ixx="0.1" ixy="0.0" ixz="0.0" iyy="0.1" iyz="0.0" izz="0.1"/>
    </inertial>
  </link>
  
  <link name="panda_finger_link2">
    <visual>
      <origin rpy="0 0 3.14159265359" xyz="0 0 0"/>
      <geometry>
        <mesh filename="package://meshes/visual/finger.obj"/>
      </geometry>
      <material name="panda_gray"/>
    </visual>
    <collision>
      <origin rpy="0 0 3.14159265359" xyz="0 0 0"/>
      <geometry>
        <mesh filename="package://meshes/collision/finger.obj"/>
      </geometry>
      <material name="panda_gray"/>
    </collision>
    <inertial>
      <origin xyz="0 0 0" rpy="0 0 0"/>
      <mass value="0.01"/>
      <inertia ixx="0.1" ixy="0.0" ixz="0.0" iyy="0.1" iyz="0.0" izz="0.1"/>
    </inertial>
  </link>
  
  <joint name="panda_finger_joint1" type="prismatic">
    <parent link="panda_hand"/>
    <child link="panda_finger_link1"/>
    <origin rpy="0 0 0" xyz="0 0 0.0584"/>
    <axis xyz="0 1 0"/>
    <limit effort="20" lower="0.0" upper="0.04" velocity="0.2"/>
  </joint>
  
  <joint name="panda_finger_joint2" type="prismatic">
    <parent link="panda_hand"/>
    <child link="panda_finger_link2"/>
    <origin rpy="0 0 0" xyz="0 0 0.0584"/>
    <axis xyz="0 -1 0"/>
    <limit effort="20" lower="0.0" upper="0.04" velocity="0.2"/>
    <mimic joint="panda_finger_joint1"/>
  </joint>
  
  
  <material name="panda_white">
    <color rgba="1. 1. 1. 1."/>
  </material>
  <material name="panda_gray">
    <color rgba=".8 .8 .8 1."/>
  </material>

</robot>
